Workbook

Sheet SIMULACIONES
A1: TRANSCEIVER | B1: PARAMETRO | C1: NEUQUEN - BAHIA BLANCA [dB] | D1: NEUQUEN - CALETA OLIVIA [dB] | E1: NEUQUEN - RIO GALLEGOS [dB] | F1: RIO GALLEGOS - SAN SEBASTIAN [dB] | G1: SAN SEBASTIAN - USHUAIA [dB] | H1: RIO GALLEGOS - ESTACION CULLEN [dB] | I1: ESTACION CULLEN - RIO GRANDE [dB] | J1: RIO GRANDE - TOLHUIN [dB] | K1: NEUQUEN - BAHIA BLANCA [dB] | L1: NEUQUEN - SAN RAFAEL [dB] | M1: RIO GALLEGOS - CALETA OLIVIA [dB] | N1: SANTA ISABEL - NEUQUEN [dB] | O1: BAHIA BLANCA - CALETA OLIVIA [dB] | P1: BAHIA BLANCA - RIO GALLEGOS [dB] | Q1: RIO GALLEGOS - NEUQUEN [dB] | R1: CALETA OLVIA - NEUQUEN [dB]
A2: Smartoptics QSFP-DD TQD011-TUNC-SO | B2: DISTANCIA | C2: GSNR = 20.87 | OSNR = 22.67 | MARGEN = 5.37 | D2: GSNR = 16.94 | OSNR = 18.26 | MARGEN = 1.44 | E2: GSNR = 15.64 | OSNR = 16.72 | MARGEN = 0.14 | F2: GSNR = 23.55 | OSNR = 25.05 | MARGEN = 8.05 | G2: GSNR = 23.03 | OSNR = 25.16 | MARGEN = 7.53 | H2: GSNR = 24.69 | OSNR = 26.47 | MARGEN = 9.19 | I2: GSNR = 26.32 | OSNR = 26.72 | MARGEN = 10.82 | J2: GSNR = 26.31 | OSNR = 28.82 | MARGEN = 10.81 | K2: GSNR = 22.02 | OSNR = 22.86 | MARGEN = 6.52 | L2: GSNR = 16.97 | OSNR = 18.25 | MARGEN = 1.47 | M2: GSNR = 21.54 | OSNR = 21.88 | MARGEN = 6.04 | N2: GSNR = 22.39 | OSNR = 24.12 | MARGEN = 6.89 | O2: GSNR = 17.94 | OSNR = 19.12 | MARGEN = 2.44 | P2: GSNR = 16.41 | OSNR = 17.32 | MARGEN = 0.91 | Q2: GSNR = 14.99 | OSNR = 16.55 | MARGEN = -0.51 | R2: GSNR = 16.45 | OSNR = 17.80 | MARGEN = 0.95
B3: GSNR | C3: GSNR = 20.87 | OSNR = 22.67 | MARGEN = 5.37 | D3: GSNR = 16.94 | OSNR = 18.26 | MARGEN = 1.44 | E3: GSNR = 15.64 | OSNR = 16.72 | MARGEN = 0.14 | F3: GSNR = 23.55 | OSNR = 25.05 | MARGEN = 8.05 | G3: GSNR = 23.03 | OSNR = 25.16 | MARGEN = 7.53 | H3: GSNR = 24.69 | OSNR = 26.47 | MARGEN = 9.19 | I3: GSNR = 26.32 | OSNR = 26.72 | MARGEN = 10.82 | J3: GSNR = 26.31 | OSNR = 28.82 | MARGEN = 10.81 | K3: GSNR = 22.02 | OSNR = 22.86 | MARGEN = 6.52 | L3: GSNR = 16.97 | OSNR = 18.25 | MARGEN = 1.47 | M3: GSNR = 21.54 | OSNR = 21.88 | MARGEN = 6.04 | N3: GSNR = 22.39 | OSNR = 24.12 | MARGEN = 6.89 | O3: GSNR = 17.94 | OSNR = 19.12 | MARGEN = 2.44 | P3: GSNR = 16.41 | OSNR = 17.32 | MARGEN = 0.91 | Q3: GSNR = 14.99 | OSNR = 16.55 | MARGEN = -0.51 | R3: GSNR = 16.45 | OSNR = 17.80 | MARGEN = 0.95
A4: Smartoptics QSFP28 TQ2025-TUNx | B4: DISTANCIA | C4: GSNR = 20.81 | OSNR = 22.92 | MARGEN = 4.31 | D4: GSNR = 16.83 | OSNR = 18.35 | MARGEN = 0.33 | E4: GSNR = 15.55 | OSNR = 16.78 | MARGEN = -0.95 | F4: GSNR = 23.66 | OSNR = 25.49 | MARGEN = 7.16 | G4: GSNR = 23.04 | OSNR = 25.61 | MARGEN = 6.54 | H4: GSNR = 24.85 | OSNR = 27.09 | MARGEN = 8.35 | I4: GSNR = 26.85 | OSNR = 27.38 | MARGEN = 10.35 | J4: GSNR = 26.59 | OSNR = 29.94 | MARGEN = 10.09 | K4: GSNR = 22.11 | OSNR = 23.12 | MARGEN = 5.61 | L4: GSNR = 16.87 | OSNR = 18.35 | MARGEN = 0.37 | M4: GSNR = 21.68 | OSNR = 22.09 | MARGEN = 5.18 | N4: GSNR = 22.41 | OSNR = 24.48 | MARGEN = 5.91 | O4: GSNR = 17.87 | OSNR = 19.23 | MARGEN = 1.37 | P4: GSNR = 16.35 | OSNR = 17.39 | MARGEN = -0.15 | Q4: GSNR = 14.84 | OSNR = 16.61 | MARGEN = -1.66 | R4: GSNR = 16.34 | OSNR = 17.88 | MARGEN = -0.16
B5: GSNR | C5: GSNR = 20.81 | OSNR = 22.92 | MARGEN = 4.31 | D5: GSNR = 16.83 | OSNR = 18.35 | MARGEN = 0.33 | E5: GSNR = 15.55 | OSNR = 16.78 | MARGEN = -0.95 | F5: GSNR = 23.66 | OSNR = 25.49 | MARGEN = 7.16 | G5: GSNR = 23.04 | OSNR = 25.61 | MARGEN = 6.54 | H5: GSNR = 24.85 | OSNR = 27.09 | MARGEN = 8.35 | I5: GSNR = 26.85 | OSNR = 27.38 | MARGEN = 10.35 | J5: GSNR = 26.59 | OSNR = 29.94 | MARGEN = 10.09 | K5: GSNR = 22.11 | OSNR = 23.12 | MARGEN = 5.61 | L5: GSNR = 16.87 | OSNR = 18.35 | MARGEN = 0.37 | M5: GSNR = 21.68 | OSNR = 22.09 | MARGEN = 5.18 | N5: GSNR = 22.41 | OSNR = 24.48 | MARGEN = 5.91 | O5: GSNR = 17.87 | OSNR = 19.23 | MARGEN = 1.37 | P5: GSNR = 16.35 | OSNR = 17.39 | MARGEN = -0.15 | Q5: GSNR = 14.84 | OSNR = 16.61 | MARGEN = -1.66 | R5: GSNR = 16.34 | OSNR = 17.88 | MARGEN = -0.16
A6: Smartoptics QSFP-DD TQD013-TUNC-SO | B6: DISTANCIA | C6: GSNR = 21.00 | OSNR = 22.87 | MARGEN = 9.50 | D6: GSNR = 16.99 | OSNR = 18.33 | MARGEN = 5.49 | E6: GSNR = 15.68 | OSNR = 16.76 | MARGEN = 4.18 | F6: GSNR = 23.79 | OSNR = 25.40 | MARGEN = 12.29 | G6: GSNR = 23.24 | OSNR = 25.52 | MARGEN = 11.74 | H6: GSNR = 25.00 | OSNR = 26.96 | MARGEN = 13.50 | I6: GSNR = 26.79 | OSNR = 27.24 | MARGEN = 15.29 | J6: GSNR = 26.78 | OSNR = 29.70 | MARGEN = 15.28 | K6: GSNR = 22.19 | OSNR = 23.07 | MARGEN = 10.69 | L6: GSNR = 17.02 | OSNR = 18.32 | MARGEN = 5.52 | M6: GSNR = 21.69 | OSNR = 22.05 | MARGEN = 10.19 | N6: GSNR = 22.57 | OSNR = 24.40 | MARGEN = 11.07 | O6: GSNR = 18.01 | OSNR = 19.21 | MARGEN = 6.51 | P6: GSNR = 16.46 | OSNR = 17.37 | MARGEN = 4.96 | Q6: GSNR = 15.02 | OSNR = 16.59 | MARGEN = 3.52 | R6: GSNR = 16.50 | OSNR = 17.86 | MARGEN = 5.00
B7: GSNR | C7: GSNR = 21.00 | OSNR = 22.87 | MARGEN = 9.50 | D7: GSNR = 16.99 | OSNR = 18.33 | MARGEN = 5.49 | E7: GSNR = 15.68 | OSNR = 16.76 | MARGEN = 4.18 | F7: GSNR = 23.79 | OSNR = 25.40 | MARGEN = 12.29 | G7: GSNR = 23.24 | OSNR = 25.52 | MARGEN = 11.74 | H7: GSNR = 25.00 | OSNR = 26.96 | MARGEN = 13.50 | I7: GSNR = 26.79 | OSNR = 27.24 | MARGEN = 15.29 | J7: GSNR = 26.78 | OSNR = 29.70 | MARGEN = 15.28 | K7: GSNR = 22.19 | OSNR = 23.07 | MARGEN = 10.69 | L7: GSNR = 17.02 | OSNR = 18.32 | MARGEN = 5.52 | M7: GSNR = 21.69 | OSNR = 22.05 | MARGEN = 10.19 | N7: GSNR = 22.57 | OSNR = 24.40 | MARGEN = 11.07 | O7: GSNR = 18.01 | OSNR = 19.21 | MARGEN = 6.51 | P7: GSNR = 16.46 | OSNR = 17.37 | MARGEN = 4.96 | Q7: GSNR = 15.02 | OSNR = 16.59 | MARGEN = 3.52 | R7: GSNR = 16.50 | OSNR = 17.86 | MARGEN = 5.00
A8: Smartoptics QSFP-DD TQD014-TUNC-SO | B8: DISTANCIA | C8: GSNR = 21.06 | OSNR = 22.96 | MARGEN = 9.06 | D8: GSNR = 17.93 | OSNR = 18.29 | MARGEN = 5.93 | E8: GSNR = 15.69 | OSNR = 16.79 | MARGEN = 3.69 | F8: GSNR = 23.91 | OSNR = 25.57 | MARGEN = 11.91 | G8: GSNR = 23.34 | OSNR = 25.69 | MARGEN = 11.34 | H8: GSNR = 25.15 | OSNR = 27.20 | MARGEN = 13.15 | I8: GSNR = 27.02 | OSNR = 27.50 | MARGEN = 15.02 | J8: GSNR = 27.01 | OSNR = 30.16 | MARGEN = 15.01 | K8: GSNR = 22.27 | OSNR = 23.16 | MARGEN = 10.27 | L8: GSNR = 17.05 | OSNR = 18.36 | MARGEN = 5.05 | M8: GSNR = 21.76 | OSNR = 22.12 | MARGEN = 9.76 | N8: GSNR = 22.67 | OSNR = 24.54 | MARGEN = 10.67 | O8: GSNR = 18.04 | OSNR = 19.25 | MARGEN = 6.04 | P8: GSNR = 16.48 | OSNR = 17.40 | MARGEN = 4.48 | Q8: GSNR = 15.03 | OSNR = 16.62 | MARGEN = 3.03 | R8: GSNR = 16.52 | OSNR = 17.89 | MARGEN = 4.52
B9: GSNR | C9: GSNR = 21.06 | OSNR = 22.96 | MARGEN = 9.06 | D9: GSNR = 17.93 | OSNR = 18.29 | MARGEN = 5.93 | E9: GSNR = 15.69 | OSNR = 16.79 | MARGEN = 3.69 | F9: GSNR = 23.91 | OSNR = 25.57 | MARGEN = 11.91 | G9: GSNR = 23.34 | OSNR = 25.69 | MARGEN = 11.34 | H9: GSNR = 25.15 | OSNR = 27.20 | MARGEN = 13.15 | I9: GSNR = 27.02 | OSNR = 27.50 | MARGEN = 15.02 | J9: GSNR = 27.01 | OSNR = 30.16 | MARGEN = 15.01 | K9: GSNR = 22.27 | OSNR = 23.16 | MARGEN = 10.27 | L9: GSNR = 17.05 | OSNR = 18.36 | MARGEN = 5.05 | M9: GSNR = 21.76 | OSNR = 22.12 | MARGEN = 9.76 | N9: GSNR = 22.67 | OSNR = 24.54 | MARGEN = 10.67 | O9: GSNR = 18.04 | OSNR = 19.25 | MARGEN = 6.04 | P9: GSNR = 16.48 | OSNR = 17.40 | MARGEN = 4.48 | Q9: GSNR = 15.03 | OSNR = 16.62 | MARGEN = 3.03 | R9: GSNR = 16.52 | OSNR = 17.89 | MARGEN = 4.52
A10: Smartoptics QSFP-DD TQD017-TUNC-SO | B10: DISTANCIA | C10: GSNR = 21.13 | OSNR = 22.87 | MARGEN = 9.33 | D10: GSNR = 17.09 | OSNR = 18.33 | MARGEN = 5.29 | E10: GSNR = 15.76 | OSNR = 16.76 | MARGEN = 3.96 | F10: GSNR = 23.91 | OSNR = 25.40 | MARGEN = 12.11 | G10: GSNR = 23.40 | OSNR = 25.52 | MARGEN = 11.60 | H10: GSNR = 25.15 | OSNR = 26.96 | MARGEN = 13.35 | I10: GSNR = 26.83 | OSNR = 27.24 | MARGEN = 15.03 | J10: GSNR = 26.97 | OSNR = 29.70 | MARGEN = 15.17 | K10: GSNR = 22.26 | OSNR = 23.07 | MARGEN = 10.46 | L10: GSNR = 17.12 | OSNR = 18.32 | MARGEN = 5.32 | M10: GSNR = 21.72 | OSNR = 22.05 | MARGEN = 9.92 | N10: GSNR = 22.71 | OSNR = 24.40 | MARGEN = 10.91 | O10: GSNR = 18.10 | OSNR = 19.21 | MARGEN = 6.30 | P10: GSNR = 16.53 | OSNR = 17.37 | MARGEN = 4.73 | Q10: GSNR = 15.14 | OSNR = 16.59 | MARGEN = 3.34 | R10: GSNR = 16.60 | OSNR = 17.86 | MARGEN = 4.80
B11: GSNR | C11: GSNR = 21.13 | OSNR = 22.87 | MARGEN = 9.33 | D11: GSNR = 17.09 | OSNR = 18.33 | MARGEN = 5.29 | E11: GSNR = 15.76 | OSNR = 16.76 | MARGEN = 3.96 | F11: GSNR = 23.91 | OSNR = 25.40 | MARGEN = 12.11 | G11: GSNR = 23.40 | OSNR = 25.52 | MARGEN = 11.60 | H11: GSNR = 25.15 | OSNR = 26.96 | MARGEN = 13.35 | I11: GSNR = 26.83 | OSNR = 27.24 | MARGEN = 15.03 | J11: GSNR = 26.97 | OSNR = 29.70 | MARGEN = 15.17 | K11: GSNR = 22.26 | OSNR = 23.07 | MARGEN = 10.46 | L11: GSNR = 17.12 | OSNR = 18.32 | MARGEN = 5.32 | M11: GSNR = 21.72 | OSNR = 22.05 | MARGEN = 9.92 | N11: GSNR = 22.71 | OSNR = 24.40 | MARGEN = 10.91 | O11: GSNR = 18.10 | OSNR = 19.21 | MARGEN = 6.30 | P11: GSNR = 16.53 | OSNR = 17.37 | MARGEN = 4.73 | Q11: GSNR = 15.14 | OSNR = 16.59 | MARGEN = 3.34 | R11: GSNR = 16.60 | OSNR = 17.86 | MARGEN = 4.80
A15: SOLO 100 Gbps
A16: HASTA 400 Gbps
A17: CAMINO PRINCIPAL
A18: CAMINO PUNTO A PUNTO
A19: CAMINO SECUNDARIO

Sheet TRAMO MAS COMPROMETIDO
A1: INICIO | B1: DESTINO | C1: DISTANCIA (Km) | D1: DISTANCIA ACUMULADA (Km) | E1: EQUIPO - EQUIPO
A2: Rio Gallegos | B2: Coy Aike | C2: 87 | D2: 87 | E2: ROADM - ILA
A3: Coy Aike | B3: Cañadon de las Vacas | C3: 75 | D3: =D2+C3 -> 162 | E3: ILA - ILA
A4: Cañadon de las Vacas | B4: Luis Piedrabuena | C4: 78 | D4: =D3+C4 -> 240 | E4: ILA - ROADM
A5: Luis Piedrabuena | B5: Lago Posadas | C5: 34 | D5: =D4+C5 -> 274 | E5: ROADM - ILA
A6: Lago Posadas | B6: Puerto San Julian | C6: 90 | D6: =D5+C6 -> 364 | E6: ILA - ROADM
A7: Puerto San Julian | B7: El Salado | C7: 74 | D7: =D6+C7 -> 438 | E7: ROADM - ILA
A8: El Salado | B8: Tres Cerros | C8: 67 | D8: =D7+C8 -> 505 | E8: ILA - ILA
A9: Tres Cerros | B9: Estancia La Calandria | C9: 66 | D9: =D8+C9 -> 571 | E9: ILA - ILA
A10: Estancia La Calandria | B10: Jaramillo | C10: 81 | D10: =D9+C10 -> 652 | E10: ILA - ROADM
A11: Jaramillo | B11: Caleta Olivia | C11: 25 | D11: =D10+C11 -> 677 | E11: ROADM - ROADM
A12: Caleta Olivia | B12: Comodoro Rivadavia | C12: 84 | D12: =D11+C12 -> 761 | E12: ROADM - ROADM
A13: Comodoro Rivadavia | B13: Astra | C13: 19 | D13: =D12+C13 -> 780 | E13: ROADM - ILA
A14: Astra | B14: Pampa Salamanca | C14: 60 | D14: =D13+C14 -> 840 | E14: ILA - ILA
... A30: Teniente Origone | B30: Bahia Blanca | C30: 74 | D30: =D29+C30 -> 2003 | E30: ILA - ROADM

Sheet DATOS DE EQUIPOS
A1: DATA SHEETS
A2: TRANSCEIVER: Smartoptics QSFP-DD TQD013-TUNC-SO
A3: ROADM: D7000-ROADM-09T
A4: EDFA: DCP-F-A22
A7: TRANSCEIVER (Open ZR+) | D7: ROADM | G7: EDFA | J7: MUX/DEMUX | M7: FIBRA | Q7: No linealidades | T7: MODULO COMPENSADOR
A8: Tx | D8: VOA ajustable | E8: - (0 a 19) dB | G8: Figura de Ruido(dB) | H8: 5.5 | J8: Perdida de insercion de entrada maxima(dB) | K8: -6 | M8: Atenuación 1 (dB/km) | N8: 0.21 | O8: Dependen del tramo | Q8: Cantidad de spans entre Tx y Rx | R8: 1 | T8: Longitud (km) | U8: 80
A9: Potencia Minima (dBm) | B9: 1 | D9: Ganancia del preamplificador(dB) | E9: 22 | G9: Ganancia maxima del amplificador(dB) | H9: 22 | J9: PMD maximo(ps/nm) | K9: 0.5 | M9: Atenuación 2 (dB/km) | N9: 0.23 | Q9: γ (Coef. de propagación no lineal en (W.km)^-1) | R9: 0.86 | T9: D.L (ps/nm) | U9: -1340
A10: Potencia Maxima (dBm) | B10: 11 | D10: Figura de Ruido preamplificador(dB) | E10: 8 | G10: Potencia Maxima de Salida(dBm) | H10: 22.5 | M10: Area efectiva para SMF (micrometro^2) | N10: 85 | Q10: |β2| (s^2/km) | R10: =-(1550^2)*N12/(2*PI()*300000) -> -22.942185 | T10: Dispersión Cromática (ps/(nm.km)) | U10: =U9/U8 -> -16.75
A11: OSNR inband (dB) | B11: 38 | D11: Perdida de insercion de entrada(dB) | E11: 5 | G11: Sensibilidad maxima de entrada (dBm) | H11: -34 | M11: Indice no lineal (ñ) | N11: =1.8*10^-8 -> 1.8e-08 | Q11: Número de canales en el enlace | R11: 40 | T11: Pérdida de inserción | U11: 7,2 dB
A12: OSNR out of band (dB) | B12: 42 | D12: Potencia de saturacion(dBm) | E12: 15 | G12: VOA ajustable | H12: - (0 a 19) dB | M12: Dispersión Cromática (ps/(nm.km)) @ 1550nm | N12: 18 | Q12: Tasa de símbolos (Baudios) | R12: =30.14*10^9 -> 30140000000 | T12: PMD (ps) | U12: 0.5
A13: Dispersion cromatica (ps/nm) (D*L) | B13: 100000 | D13: Ganancia optica Booster Amplifier (dB) | E13: 18 | M13: λ0 (Dispersión cero) | N13: 1310 | O13: 1300-1324 nm | Q13: Ancho de banda del canal (Hz) | R13: =12.5*10^9 -> 12500000000
A14: B0 | B14: =12.5*10^9 -> 12500000000 | D14: Figura de Ruido booster(dB) | E14: 6.5 | M14: Pendiente en λ0 (Dispersión cero) (ps/(nm^2.km)) | N14: 0.092
A15: GSNR a 0,1nm (dB) | B15: 35.18 | D15: Sensibilidad máxima entrada A/D | E15: -20 | M15: Coeficiente PMD (ps/√km) | N15: 0.1
A16: Rx | D16: Sensibilidad maxima de entrada line(dBm) | E16: -35
A17: Sensibilidad (dBm) | B17: -32 | D17: Potencia de salida line | E17: =E15-E11+E13 -> -7
A18: BER | D18: Potencia de salida A/D | E18: =E16-E11+E9 -> -18
A19: Z (Q) | D19: Rango de frecuencias (THz) | E19: 191.35-196.1
A20: MOD (NRZ) | D20: Rango de longitudes de onda (nm) | E20: 1528-1567.5
A21: B filtro (GHz) | D21: Potencia de saturación Booster (dBm) | E21: =23-18-10*LOG10(40) -> -11.0206
A22: Required OSNR (dB) @ Prx (dBm) | B22: 11.5 dB @ -20 dBm | D22: Potencia de saturación Preamplificador (dBm) | E22: =23-22-10*LOG10(40) -> -15.0206 | G22: son 48 canales pero solo 40 llevan potencia

Sheet PP - OSNR - GSNR
B1: PRESUPUESTO DE POTENCIA | G1: FIGURA DE RUIDO (dB) | H1: OSNR CANAL (dB) | I1: OSNR CANAL EN VECES | J1: OSNR ACUMULADA EN VECES | K1: OSNR ACUMULADA (dB) | L1: 1/GSNR_NL | M1: GSNR_NL EN VECES | N1: GSNR_NL (dB) | O1: GSNR_NL ACUMULADA EN VECES | P1: GSNR_NL ACUMULADA (dB)
A3: Tramo: Rio Gallegos - Bahía Blanca | B3: Distancia (Km) | C3: Atenuación por km | D3: Amplificación/Atenuación (dB) | E3: Potencia acumulada (dBm) | F3: 100 Gbps | Z3: B0 es el AB equivalente del ruido
A5: ='TRAMO MAS COMPROMETIDO'!A2 -> Rio Gallegos | B5: Transceiver + ROADM
A6: Transceiver | D6: ='DATOS DE EQUIPOS'!B9 -> 1 | E6: =D6 -> 1 | G6: ='DATOS DE EQUIPOS'!B11 -> 38 | H6: 38 | I6: =10^(H6/10) -> 6309.5734 | J6: =HARMEAN(I6)/1 -> 6309.5734 | K6: =10*LOG10(J6) -> 38 | M6: =10^(N6/10) -> 3296.0971 | N6: 35.18 | O6: =HARMEAN(M6)/1 -> 3296.0971 | P6: =10*LOG(O6) -> 35.18
A7: Mux/Demux | D7: -6 | E7: =D7+E6 -> -5
A8: A/D - Line out (ROADM 2) | D8: -5 | E8: =D8+E7 -> -10
A9: VOA | D9: =IF(E8 > -14.8, -14.8 - E8, 0) -> -4.8 | E9: =D9+E8 -> -14.8
A10: Amplificador Booster | D10: 18 | E10: =D10+E9 -> 3.2 | G10: ='DATOS DE EQUIPOS'!E14 -> 6.5 | H10: =E9+158.9-10*LOG10('DATOS DE EQUIPOS'!B14)-G10 -> 36.6309 | I10: =10^(H10/10) -> 4603.5195 | J10: =HARMEAN(I6:I10)/2 -> 2661.596 | K10: =10*LOG10(J10) -> 34.251421 | L10: =(2/3)^3*'DATOS DE EQUIPOS'!$R$8*'DATOS DE EQUIPOS'!$R$9^2*'NO LINEALIDADES'!E3*(10^(E10/10)*0.001)^2*LOG10(PI()^2*ABS('DATOS DE EQUIPOS'!$R$10*10^(-24))*'NO LINEALIDADES'!E3*'DATOS DE EQUIPOS'!$R$11^2*'DATOS DE EQUIPOS'!$R$12^2)*'DATOS DE EQUIPOS'!$R$13/(PI()*ABS('DATOS DE EQUIPOS'!$R$10*10^(-24))*'DATOS DE EQUIPOS'!$R$12^3) -> 0.00042919621 | M10: =1/L10 -> 2329.9367 | N10: =10*LOG10(M10) -> 33.673441 | O10: =HARMEAN(M6:M10)/2 -> 1365.0287 | P10: =10*LOG(O10) -> 31.351418
A11: Fibra | B11: ='TRAMO MAS COMPROMETIDO'!C2 -> 87 | C11: -0.235 | D11: =B11*C11 -> -20.445 | E11: =D11+E10 -> -17.245
A13: ='TRAMO MAS COMPROMETIDO'!A3 -> Coy Aike | B13: Agregado
A14: VOA | D14: =IF(D15 > 0, IF(E11 > -18.8, -18.8 - E11, 0), 0) -> -1.555 | E14: =D14+E11 -> -18.8
A15: EDFA | D15: 22 | E15: =D15+E14 -> 3.2 | G15: ='DATOS DE EQUIPOS'!H8 -> 5.5 | H15: =E14+158.9-10*LOG10('DATOS DE EQUIPOS'!B14)-G15 -> 33.6309 | I15: =10^(H15/10) -> 2307.2252 | J15: =HARMEAN(I6:I15)/3 -> 1235.887 | K15: =10*LOG10(J15) -> 30.919788 | L15: =(2/3)^3*'DATOS DE EQUIPOS'!$R$8*'DATOS DE EQUIPOS'!$R$9^2*'NO LINEALIDADES'!E4*(10^(E15/10)*0.001)^2*LOG10(PI()^2*ABS('DATOS DE EQUIPOS'!$R$10*10^(-24))*'NO LINEALIDADES'!E4*'DATOS DE EQUIPOS'!$R$11^2*'DATOS DE EQUIPOS'!$R$12^2)*'DATOS DE EQUIPOS'!$R$13/(PI()*ABS('DATOS DE EQUIPOS'!$R$10*10^(-24))*'DATOS DE EQUIPOS'!$R$12^3) -> 0.000424917 | M15: =1/L15 -> 2353.4008 | N15: =10*LOG10(M15) -> 33.716959 | O15: =HARMEAN(M6:M15)/3 -> 863.92915 | P15: =10*LOG(O15) -> 29.364781
A16: Fibra | B16: ='TRAMO MAS COMPROMETIDO'!C3 -> 75 | C16: -0.235 | D16: =B16*C16 -> -17.625 | E16: =D16+E15 -> -14.425
A18: ='TRAMO MAS COMPROMETIDO'!A4 -> Cañadon de las Vacas | B18: Agregado
A19: VOA | D19: =IF(D20 > 0, IF(E16 > -18.8, -18.8 - E16, 0), 0) -> -4.375 | E19: =D19+E16 -> -18.8
A20: EDFA | D20: 22 | E20: =D20+E19 -> 3.2 | G20: ='DATOS DE EQUIPOS'!H8 -> 5.5 | H20: =E19+158.9-10*LOG10('DATOS DE EQUIPOS'!B14)-G20 -> 33.6309 | I20: =10^(H20/10) -> 2307.2252 | J20: =HARMEAN(I6:I20)/4 -> 804.79235 | K20: =10*LOG10(J20) -> 29.056838 | L20: =(2/3)^3*'DATOS DE EQUIPOS'!$R$8*'DATOS DE EQUIPOS'!$R$9^2*'NO LINEALIDADES'!E5*(10^(E20/10)*0.001)^2*LOG10(PI()^2*ABS('DATOS DE EQUIPOS'!$R$10*10^(-24))*'NO LINEALIDADES'!E5*'DATOS DE EQUIPOS'!$R$11^2*'DATOS DE EQUIPOS'!$R$12^2)*'DATOS DE EQUIPOS'!$R$13/(PI()*ABS('DATOS DE EQUIPOS'!$R$10*10^(-24))*'DATOS DE EQUIPOS'!$R$12^3) -> 0.00042625309 | M20: =1/L20 -> 2346.024 | N20: =10*LOG10(M20) -> 33.703325 | O20: =HARMEAN(M16:M20)/4 -> 586.50601 | P20: =10*LOG(O20) -> 27.682725
A21: Fibra | B21: ='TRAMO MAS COMPROMETIDO'!C4 -> 78 | C21: -0.235 | D21: =B21*C21 -> -18.33 | E21: =D21+E20 -> -15.13
A23: ='TRAMO MAS COMPROMETIDO'!A5 -> Luis Piedrabuena
A24: VOA (ROADM 1) | D24: =IF(D25 > 0, IF(E21 > -18.8, -18.8 - E21, 0), 0) -> -3.67 | E24: =D24+E21 -> -18.8
A25: Preamplificador (ROADM 1) | D25: 22 | E25: =D25+E24 -> 3.2 | G25: ='DATOS DE EQUIPOS'!E10 -> 8 | H25: =E24+158.9-10*LOG10('DATOS DE EQUIPOS'!B14)-G25 -> 31.1309 | I25: =10^(H25/10) -> 1297.4481 | J25: =HARMEAN(I6:I25)/5 -> 496.69689 | K25: =10*LOG10(J25) -> 26.960914
A26: Line in - A/D (ROADM 1) | D26: -5 | E26: =D26+E25 -> -1.8
A27: A/D - Line out (ROADM 2) | D27: -5 | E27: =D27+E26 -> -6.8
A28: VOA | D28: =IF(E27 > -14.8, -14.8 - E27, 0) -> -8 | E28: =D28+E27 -> -14.8
A29: Amplificador Booster (ROADM 2) | D29: 18 | E29: =D29+E28 -> 3.2 | G29: ='DATOS DE EQUIPOS'!E14 -> 6.5 | H29: =E28+158.9-10*LOG10('DATOS DE EQUIPOS'!B14)-G29 -> 36.6309 | I29: =10^(H29/10) -> 4603.5195 | J29: =HARMEAN(I6:I29)/6 -> 448.32486 | K29: =10*LOG10(J29) -> 26.515928 | L29: =(2/3)^3*'DATOS DE EQUIPOS'!$R$8*'DATOS DE EQUIPOS'!$R$9^2*'NO LINEALIDADES'!E6*(10^(E29/10)*0.001)^2*LOG10(PI()^2*ABS('DATOS DE EQUIPOS'!$R$10*10^(-24))*'NO LINEALIDADES'!E6*'DATOS DE EQUIPOS'!$R$11^2*'DATOS DE EQUIPOS'!$R$12^2)*'DATOS DE EQUIPOS'!$R$13/(PI()*ABS('DATOS DE EQUIPOS'!$R$10*10^(-24))*'DATOS DE EQUIPOS'!$R$12^3) -> 0.00035482999 | M29: =1/L29 -> 2818.2511 | N29: =10*LOG10(M29) -> 34.499797 | O29: =HARMEAN(M6:M29)/5 -> 515.84005 | P29: =10*LOG(O29) -> 27.125151
A30: Fibra | B30: ='TRAMO MAS COMPROMETIDO'!C5 -> 34 | C30: -0.235 | D30: =B30*C30 -> -7.99 | E30: =D30+E29 -> -4.79
A32: ='TRAMO MAS COMPROMETIDO'!A6 -> Lago Posadas | B32: Agregado
A33: VOA | D33: =IF(D34 > 0, IF(E30 > -18.8, -18.8 - E30, 0), 0) -> -14.01 | E33: =D33+E30 -> -18.8
A34: EDFA | D34: 22 | E34: =D34+E33 -> 3.2 | G34: ='DATOS DE EQUIPOS'!H8 -> 5.5 | H34: =E33+158.9-10*LOG10('DATOS DE EQUIPOS'!B14)-G34 -> 33.6309 | I34: =10^(H34/10) -> 2307.2252 | J34: =HARMEAN(I6:I34)/7 -> 375.38292 | K34: =10*LOG10(J34) -> 25.744745 | L34: =(2/3)^3*'DATOS DE EQUIPOS'!$R$8*'DATOS DE EQUIPOS'!$R$9^2*'NO LINEALIDADES'!E7*(10^(E34/10)*0.001)^2*LOG10(PI()^2*ABS('DATOS DE EQUIPOS'!$R$10*10^(-24))*'NO LINEALIDADES'!E7*'DATOS DE EQUIPOS'!$R$11^2*'DATOS DE EQUIPOS'!$R$12^2)*'DATOS DE EQUIPOS'!$R$13/(PI()*ABS('DATOS DE EQUIPOS'!$R$10*10^(-24))*'DATOS DE EQUIPOS'!$R$12^3) -> 0.0004299045 | M34: =1/L34 -> 2326.098 | N34: =10*LOG10(M34) -> 33.66628 | O34: =HARMEAN(M6:M34)/6 -> 422.20995 | P34: =10*LOG(O34) -> 26.255285
A35: Fibra | B35: ='TRAMO MAS COMPROMETIDO'!C6 -> 90 | C35: -0.235 | D35: =B35*C35 -> -21.15 | E35: =D35+E34 -> -17.95
A37: ='TRAMO MAS COMPROMETIDO'!A7 -> Puerto San Julian
A38: VOA (ROADM 1) | D38: =IF(D39 > 0, IF(E35 > -18.8, -18.8 - E35, 0), 0) -> -0.85 | E38: =D38+E35 -> -18.8
A39: Preamplificador (ROADM 1) | D39: 22 | E39: =D39+E38 -> 3.2 | G39: ='DATOS DE EQUIPOS'!E10 -> 8 | H39: =E38+158.9-10*LOG10('DATOS DE EQUIPOS'!B14)-G39 -> 31.1309 | I39: =10^(H39/10) -> 1297.4481 | J39: =HARMEAN(I6:I39)/8 -> 291.14707 | K39: =10*LOG10(J39) -> 24.641124
A40: Line in - A/D (ROADM 1) | D40: -5 | E40: =D40+E39 -> -1.8
A41: A/D - Line out (ROADM 2) | D41: -5 | E41: =D41+E40 -> -6.8
A42: VOA | D42: =IF(E41 > -14.8, -14.8 - E41, 0) -> -8 | E42: =D42+E41 -> -14.8
A43: Amplificador Booster (ROADM 2) | D43: 18 | E43: =D43+E42 -> 3.2 | G43: ='DATOS DE EQUIPOS'!E14 -> 6.5 | H43: =E42+158.9-10*LOG10('DATOS DE EQUIPOS'!B14)-G43 -> 36.6309 | I43: =10^(H43/10) -> 4603.5195 | J43: =HARMEAN(I6:I43)/9 -> 273.82891 | K43: =10*LOG10(J43) -> 24.374793 | L43: =(2/3)^3*'DATOS DE EQUIPOS'!$R$8*'DATOS DE EQUIPOS'!$R$9^2*'NO LINEALIDADES'!E8*(10^(E43/10)*0.001)^2*LOG10(PI()^2*ABS('DATOS DE EQUIPOS'!$R$10*10^(-24))*'NO LINEALIDADES'!E8*'DATOS DE EQUIPOS'!$R$11^2*'DATOS DE EQUIPOS'!$R$12^2)*'DATOS DE EQUIPOS'!$R$13/(PI()*ABS('DATOS DE EQUIPOS'!$R$10*10^(-24))*'DATOS DE EQUIPOS'!$R$12^3) -> 0.00042442243 | M43: =1/L43 -> 2356.1431 | N43: =10*LOG10(M43) -> 33.722017 | O43: =HARMEAN(M6:M43)/7 -> 358.04919 | P43: =10*LOG(O43) -> 25.539427
A44: Fibra | B44: ='TRAMO MAS COMPROMETIDO'!C7 -> 74 | C44: -0.235 | D44: =B44*C44 -> -17.39 | E44: =D44+E43 -> -14.19
A46: ='TRAMO MAS COMPROMETIDO'!A8 -> El Salado | B46: Agregado
A47: VOA | D47: =IF(D48 > 0, IF(E44 > -18.8, -18.8 - E44, 0), 0) -> -4.61 | E47: =D47+E44 -> -18.8
A48: EDFA | D48: 22 | E48: =D48+E47 -> 3.2 | G48: ='DATOS DE EQUIPOS'!H8 -> 5.5 | H48: =E47+158.9-10*LOG10('DATOS DE EQUIPOS'!B14)-G48 -> 33.6309 | I48: =10^(H48/10) -> 2307.2252 | J48: =HARMEAN(I6:I48)/10 -> 244.77788 | K48: =10*LOG10(J48) -> 23.887722 | L48: =(2/3)^3*'DATOS DE EQUIPOS'!$R$8*'DATOS DE EQUIPOS'!$R$9^2*'NO LINEALIDADES'!E9*(10^(E48/10)*0.001)^2*LOG10(PI()^2*ABS('DATOS DE EQUIPOS'!$R$10*10^(-24))*'NO LINEALIDADES'!E9*'DATOS DE EQUIPOS'!$R$11^2*'DATOS DE EQUIPOS'!$R$12^2)*'DATOS DE EQUIPOS'!$R$13/(PI()*ABS('DATOS DE EQUIPOS'!$R$10*10^(-24))*'DATOS DE EQUIPOS'!$R$12^3) -> 0.00042012187 | M48: =1/L48 -> 2380.2617 | N48: =10*LOG10(M48) -> 33.766247 | O48: =HARMEAN(M6:M48)/8 -> 311.23229 | P48: =10*LOG(O48) -> 24.930847
...

Sheet NO LINEALIDADES
A1: No Linealidades
A2: INICIO | B2: DESTINO | C2: DISTANCIA (Km) | D2: Potencia de entrada a la fibra (dB) | E2: Longitud Efectiva | F2: Longitud No Lineal
A3: Rio Gallegos | B3: Coy Aike | C3: 87 | D3: ='PP - OSNR - GSNR'!E10 -> 3.2 | E3: =(1-EXP(-$J$3*C3))/$J$3 -> 18.694206 | F3: =(1.55*'DATOS DE EQUIPOS'!$N$10*0.000000001)/(2*PI()*('DATOS DE EQUIPOS'!$N$11)*10^(D3/10)*0.001) -> 557.56853 | H3: Coeficiente de atenuación de potencia (α [np/km]) | J3: ='DATOS DE EQUIPOS'!N9/4.343 -> 0.052958784
A4: Coy Aike | B4: Cañadon de las Vacas | C4: 75 | D4: ='PP - OSNR - GSNR'!E15 -> 3.2 | E4: =(1-EXP(-$J$3*C4))/$J$3 -> 18.526909 | F4: =(1.55*'DATOS DE EQUIPOS'!$N$10*0.000000001)/(2*PI()*('DATOS DE EQUIPOS'!$N$11)*10^(D4/10)*0.001) -> 557.56853
A5: Cañadon de las Vacas | B5: Luis Piedrabuena | C5: 78 | D5: ='PP - OSNR - GSNR'!E20 -> 3.2 | E5: =(1-EXP(-$J$3*C5))/$J$3 -> 18.57916 | F5: =(1.55*'DATOS DE EQUIPOS'!$N$10*0.000000001)/(2*PI()*('DATOS DE EQUIPOS'!$N$11)*10^(D5/10)*0.001) -> 557.56853
A6: Luis Piedrabuena | B6: Lago Posadas | C6: 34 | D6: ='PP - OSNR - GSNR'!E29 -> 3.2 | E6: =(1-EXP(-$J$3*C6))/$J$3 -> 15.763203 | F6: =(1.55*'DATOS DE EQUIPOS'!$N$10*0.000000001)/(2*PI()*('DATOS DE EQUIPOS'!$N$11)*10^(D6/10)*0.001) -> 557.56853
A7: Lago Posadas | B7: Puerto San Julian | C7: 90 | D7: ='PP - OSNR - GSNR'!E34 -> 3.2 | E7: =(1-EXP(-$J$3*C7))/$J$3 -> 18.721882 | F7: =(1.55*'DATOS DE EQUIPOS'!$N$10*0.000000001)/(2*PI()*('DATOS DE EQUIPOS'!$N$11)*10^(D7/10)*0.001) -> 557.56853
A8: Puerto San Julian | B8: El Salado | C8: 74 | D8: ='PP - OSNR - GSNR'!E43 -> 3.2 | E8: =(1-EXP(-$J$3*C8))/$J$3 -> 18.507563 | F8: =(1.55*'DATOS DE EQUIPOS'!$N$10*0.000000001)/(2*PI()*('DATOS DE EQUIPOS'!$N$11)*10^(D8/10)*0.001) -> 557.56853
A9: El Salado | B9: Tres Cerros | C9: 67 | D9: ='PP - OSNR - GSNR'!E48 -> 3.2 | E9: =(1-EXP(-$J$3*C9))/$J$3 -> 18.339256 | F9: =(1.55*'DATOS DE EQUIPOS'!$N$10*0.000000001)/(2*PI()*('DATOS DE EQUIPOS'!$N$11)*10^(D9/10)*0.001) -> 557.56853
A10: Tres Cerros | B10: Estancia La Calandria | C10: 66 | D10: ='PP - OSNR - GSNR'!E53 -> 3.2 | E10: =(1-EXP(-$J$3*C10))/$J$3 -> 18.309705 | F10: =(1.55*'DATOS DE EQUIPOS'!$N$10*0.000000001)/(2*PI()*('DATOS DE EQUIPOS'!$N$11)*10^(D10/10)*0.001) -> 557.56853
A11: Estancia La Calandria | B11: Jaramillo | C11: 81 | D11: ='PP - OSNR - GSNR'!E58 -> 3.2 | E11: =(1-EXP(-$J$3*C11))/$J$3 -> 18.623736 | F11: =(1.55*'DATOS DE EQUIPOS'!$N$10*0.000000001)/(2*PI()*('DATOS DE EQUIPOS'!$N$11)*10^(D11/10)*0.001) -> 557.56853
A12: Jaramillo | B12: Caleta Olivia | C12: 25 | D12: ='PP - OSNR - GSNR'!E67 -> 3.2 | E12: =(1-EXP(-$J$3*C12))/$J$3 -> 13.858381 | F12: =(1.55*'DATOS DE EQUIPOS'!$N$10*0.000000001)/(2*PI()*('DATOS DE EQUIPOS'!$N$11)*10^(D12/10)*0.001) -> 557.56853
A13: Caleta Olivia | B13: Comodoro Rivadavia | C13: 84 | D13: ='PP - OSNR - GSNR'!E76 -> 3.2 | E13: =(1-EXP(-$J$3*C13))/$J$3 -> 18.661764 | F13: =(1.55*'DATOS DE EQUIPOS'!$N$10*0.000000001)/(2*PI()*('DATOS DE EQUIPOS'!$N$11)*10^(D13/10)*0.001) -> 557.56853
A14: Comodoro Rivadavia | B14: Astra | C14: 19 | D14: ='PP - OSNR - GSNR'!E85 -> 3.2 | E14: =(1-EXP(-$J$3*C14))/$J$3 -> 11.979137 | F14: =(1.55*'DATOS DE EQUIPOS'!$N$10*0.000000001)/(2*PI()*('DATOS DE EQUIPOS'!$N$11)*10^(D14/10)*0.001) -> 557.56853
A15: Astra | B15: Pampa Salamanca | C15: 60 | D15: ='PP - OSNR - GSNR'!E90 -> 3.2 | E15: =(1-EXP(-$J$3*C15))/$J$3 -> 18.095419 | F15: =(1.55*'DATOS DE EQUIPOS'!$N$10*0.000000001)/(2*PI()*('DATOS DE EQUIPOS'!$N$11)*10^(D15/10)*0.001) -> 557.56853
A16: Pampa Salamanca | B16: Garayalde | C16: 102 | D16: ='PP - OSNR - GSNR'!E95 -> 3.2 | E16: =(1-EXP(-$J$3*C16))/$J$3 -> 18.797477 | F16: =(1.55*'DATOS DE EQUIPOS'!$N$10*0.000000001)/(2*PI()*('DATOS DE EQUIPOS'!$N$11)*10^(D16/10)*0.001) -> 557.56853
A17: Garayalde | B17: Florentino Ameghino | C17: 110 | D17: ='PP - OSNR - GSNR'!E100 -> 1.23 | E17: =(1-EXP(-$J$3*C17))/$J$3 -> 18.826878 | F17: =(1.55*'DATOS DE EQUIPOS'!$N$10*0.000000001)/(2*PI()*('DATOS DE EQUIPOS'!$N$11)*10^(D17/10)*0.001) -> 877.60331
A18: Florentino Ameghino | B18: Rawson | C18: 85 | D18: ='PP - OSNR - GSNR'!E105 -> -2.62 | E18: =(1-EXP(-$J$3*C18))/$J$3 -> 18.673156 | F18: =(1.55*'DATOS DE EQUIPOS'!$N$10*0.000000001)/(2*PI()*('DATOS DE EQUIPOS'!$N$11)*10^(D18/10)*0.001) -> 2129.601
A19: Rawson | B19: Trelew | C19: 22 | D19: ='PP - OSNR - GSNR'!E114 -> 3.2 | E19: =(1-EXP(-$J$3*C19))/$J$3 -> 12.993244 | F19: =(1.55*'DATOS DE EQUIPOS'!$N$10*0.000000001)/(2*PI()*('DATOS DE EQUIPOS'!$N$11)*10^(D19/10)*0.001) -> 557.56853
A20: Trelew | B20: Puerto Madryn | C20: 69 | D20: ='PP - OSNR - GSNR'!E123 -> 3.2 | E20: =(1-EXP(-$J$3*C20))/$J$3 -> 18.393864 | F20: =(1.55*'DATOS DE EQUIPOS'!$N$10*0.000000001)/(2*PI()*('DATOS DE EQUIPOS'!$N$11)*10^(D20/10)*0.001) -> 557.56853
A21: Puerto Madryn | B21: Arroyo Verde | C21: 100 | D21: ='PP - OSNR - GSNR'!E132 -> 3.2 | E21: =(1-EXP(-$J$3*C21))/$J$3 -> 18.787965 | F21: =(1.55*'DATOS DE EQUIPOS'!$N$10*0.000000001)/(2*PI()*('DATOS DE EQUIPOS'!$N$11)*10^(D21/10)*0.001) -> 557.56853
A22: Arroyo Verde | B22: Sierra Grande | C22: 49 | D22: ='PP - OSNR - GSNR'!E137 -> 1.7 | E22: =(1-EXP(-$J$3*C22))/$J$3 -> 17.473072 | F22: =(1.55*'DATOS DE EQUIPOS'!$N$10*0.000000001)/(2*PI()*('DATOS DE EQUIPOS'!$N$11)*10^(D22/10)*0.001) -> 787.58648
A23: Sierra Grande | B23: Las Grutas | C23: 110 | D23: ='PP - OSNR - GSNR'!E146 -> 3.2 | E23: =(1-EXP(-$J$3*C23))/$J$3 -> 18.826878 | F23: =(1.55*'DATOS DE EQUIPOS'!$N$10*0.000000001)/(2*PI()*('DATOS DE EQUIPOS'!$N$11)*10^(D23/10)*0.001) -> 557.56853
A24: Las Grutas | B24: San Antonio Oeste | C24: 18 | D24: ='PP - OSNR - GSNR'!E151 -> -0.65 | E24: =(1-EXP(-$J$3*C24))/$J$3 -> 11.603684 | F24: =(1.55*'DATOS DE EQUIPOS'!$N$10*0.000000001)/(2*PI()*('DATOS DE EQUIPOS'!$N$11)*10^(D24/10)*0.001) -> 1353.0014
A25: San Antonio Oeste | B25: Nuevo Leon | C25: 75 | D25: ='PP - OSNR - GSNR'!E160 -> 3.2 | E25: =(1-EXP(-$J$3*C25))/$J$3 -> 18.526909 | F25: =(1.55*'DATOS DE EQUIPOS'!$N$10*0.000000001)/(2*PI()*('DATOS DE EQUIPOS'!$N$11)*10^(D25/10)*0.001) -> 557.56853
A26: Nuevo Leon | B26: San Javier | C26: 91 | D26: ='PP - OSNR - GSNR'!E165 -> 3.2 | E26: =(1-EXP(-$J$3*C26))/$J$3 -> 18.730172 | F26: =(1.55*'DATOS DE EQUIPOS'!$N$10*0.000000001)/(2*PI()*('DATOS DE EQUIPOS'!$N$11)*10^(D26/10)*0.001) -> 557.56853
A27: San Javier | B27: Viedma | C27: 28 | D27: ='PP - OSNR - GSNR'!E174 -> 3.2 | E27: =(1-EXP(-$J$3*C27))/$J$3 -> 14.596431 | F27: =(1.55*'DATOS DE EQUIPOS'!$N$10*0.000000001)/(2*PI()*('DATOS DE EQUIPOS'!$N$11)*10^(D27/10)*0.001) -> 557.56853
A28: Viedma | B28: Stroeder | C28: 92 | D28: ='PP - OSNR - GSNR'!E183 -> 3.2 | E28: =(1-EXP(-$J$3*C28))/$J$3 -> 18.738035 | F28: =(1.55*'DATOS DE EQUIPOS'!$N$10*0.000000001)/(2*PI()*('DATOS DE EQUIPOS'!$N$11)*10^(D28/10)*0.001) -> 557.56853
A29: Stroeder | B29: Pedro Luro | C29: 84 | D29: ='PP - OSNR - GSNR'!E188 -> 3.2 | E29: =(1-EXP(-$J$3*C29))/$J$3 -> 18.661764 | F29: =(1.55*'DATOS DE EQUIPOS'!$N$10*0.000000001)/(2*PI()*('DATOS DE EQUIPOS'!$N$11)*10^(D29/10)*0.001) -> 557.56853
A30: Pedro Luro | B30: Teniente Origone | C30: 54 | D30: ='PP - OSNR - GSNR'!E193 -> 3.2 | E30: =(1-EXP(-$J$3*C30))/$J$3 -> 17.800981 | F30: =(1.55*'DATOS DE EQUIPOS'!$N$10*0.000000001)/(2*PI()*('DATOS DE EQUIPOS'!$N$11)*10^(D30/10)*0.001) -> 557.56853
A31: Teniente Origone | B31: Bahia Blanca | C31: 74 | D31: ='PP - OSNR - GSNR'!E198 -> 3.2 | E31: =(1-EXP(-$J$3*C31))/$J$3 -> 18.507563 | F31: =(1.55*'DATOS DE EQUIPOS'!$N$10*0.000000001)/(2*PI()*('DATOS DE EQUIPOS'!$N$11)*10^(D31/10)*0.001) -> 557.56853

Sheet DISPERSION CROMATICA
D1: DISPERSIÓN CROMATICA
D3: @ 1550 nm | F3: @ 1528.77 nm (196.10 THz) | H3: @ 1547.72 nm (193.70 THz) | J3: @ 1566.31 nm (191.40 THz)
D4: D1 [ps/(nm.km)] | E4: ='DATOS DE EQUIPOS'!N12 -> 18 | F4: D2 [ps/(nm.km)] | G4: =('DATOS DE EQUIPOS'!N14/4)*(1528.77-('DATOS DE EQUIPOS'!N13)^4/(1528.77)^3) -> 16.20397 | H4: D3 [ps/(nm.km)] | I4: =('DATOS DE EQUIPOS'!N14/4)*(1547.72-('DATOS DE EQUIPOS'!N13)^4/(1547.72)^3) -> 17.327674 | J4: D4 [ps/(nm.km)] | K4: =('DATOS DE EQUIPOS'!N14/4)*(1566.31-('DATOS DE EQUIPOS'!N13)^4/(1566.31)^3) -> 18.398071
A5: INICIO | B5: DESTINO | C5: DISTANCIA (Km) | D5: DISPERSION TRAMO | E5: DISPERSION ACUMULADA (ps/nm) | F5: DISPERSION TRAMO | G5: DISPERSION ACUMULADA (ps/nm) | H5: DISPERSION TRAMO | I5: DISPERSION ACUMULADA (ps/nm) | J5: DISPERSION TRAMO | K5: DISPERSION ACUMULADA (ps/nm)
A6: Rio Gallegos | B6: Coy Aike | C6: 87 | D6: =C6*$E$4 -> 1566 | E6: =D6 -> 1566 | F6: =C6*$G$4 -> 1409.7454 | G6: =F6 -> 1409.7454 | H6: =C6*$I$4 -> 1507.5076 | I6: =H6 -> 1507.5076 | J6: =C6*$K$4 -> 1600.6322 | K6: =J6 -> 1600.6322
A7: Coy Aike | B7: Cañadon de las Vacas | C7: 75 | D7: =C7*$E$4 -> 1350 | E7: =D7+E6 -> 2916 | F7: =C7*$G$4 -> 1215.2977 | G7: =F7+G6 -> 2625.0431 | H7: =C7*$I$4 -> 1299.5756 | I7: =H7+I6 -> 2807.0832 | J7: =C7*$K$4 -> 1379.8553 | K7: =J7+K6 -> 2980.4875
A8: Cañadon de las Vacas | B8: Luis Piedrabuena | C8: 78 | D8: =C8*$E$4 -> 1404 | E8: =D8+E7 -> 4320 | F8: =C8*$G$4 -> 1263.9097 | G8: =F8+G7 -> 3888.9528 | H8: =C8*$I$4 -> 1351.5586 | I8: =H8+I7 -> 4158.6418 | J8: =C8*$K$4 -> 1435.0495 | K8: =J8+K7 -> 4415.5371
A9: Luis Piedrabuena | B9: Lago Posadas | C9: 34 | D9: =C9*$E$4 -> 612 | E9: =D9+E8 -> 4932 | F9: =C9*$G$4 -> 550.93498 | G9: =F9+G8 -> 4439.8878 | H9: =C9*$I$4 -> 589.14092 | I9: =H9+I8 -> 4747.7827 | J9: =C9*$K$4 -> 625.53442 | K9: =J9+K8 -> 5041.0715
A10: Lago Posadas | B10: Puerto San Julian | C10: 90 | D10: =C10*$E$4 -> 1620 | E10: =D10+E9 -> 6552 | F10: =C10*$G$4 -> 1458.3573 | G10: =F10+G9 -> 5898.2451 | H10: =C10*$I$4 -> 1559.4907 | I10: =H10+I9 -> 6307.2734 | J10: =C10*$K$4 -> 1655.8264 | K10: =J10+K9 -> 6696.8979
A11: Puerto San Julian | B11: El Salado | C11: 74 | D11: =C11*$E$4 -> 1332 | E11: =D11+E10 -> 7884 | F11: =C11*$G$4 -> 1199.0938 | G11: =F11+G10 -> 7097.3388 | H11: =C11*$I$4 -> 1282.2479 | I11: =H11+I10 -> 7589.5213 | J11: =C11*$K$4 -> 1361.4573 | K11: =J11+K10 -> 8058.3551
A12: El Salado | B12: Tres Cerros | C12: 67 | D12: =C12*$E$4 -> 1206 | E12: =D12+E11 -> 9090 | F12: =C12*$G$4 -> 1085.666 | G12: =F12+G11 -> 8183.0048 | H12: =C12*$I$4 -> 1160.9542 | I12: =H12+I11 -> 8750.4754 | J12: =C12*$K$4 -> 1232.6708 | K12: =J12+K11 -> 9291.0259
A13: Tres Cerros | B13: Estancia La Calandria | C13: 66 | D13: =C13*$E$4 -> 1188 | E13: =D13+E12 -> 10278 | F13: =C13*$G$4 -> 1069.462 | G13: =F13+G12 -> 9252.4669 | H13: =C13*$I$4 -> 1143.6265 | I13: =H13+I12 -> 9894.1019 | J13: =C13*$K$4 -> 1214.2727 | K13: =J13+K12 -> 10505.299
A14: Estancia La Calandria | B14: Jaramillo | C14: 81 | D14: =C14*$E$4 -> 1458 | E14: =D14+E13 -> 11736 | F14: =C14*$G$4 -> 1312.5216 | G14: =F14+G13 -> 10564.988 | H14: =C14*$I$4 -> 1403.5416 | I14: =H14+I13 -> 11297.644 | J14: =C14*$K$4 -> 1490.2438 | K14: =J14+K13 -> 11995.542
A15: Jaramillo | B15: Caleta Olivia | C15: 25 | D15: =C15*$E$4 -> 450 | E15: =D15+E14 -> 12186 | F15: =C15*$G$4 -> 405.09925 | G15: =F15+G14 -> 10970.088 | H15: =C15*$I$4 -> 433.19185 | I15: =H15+I14 -> 11730.835 | J15: =C15*$K$4 -> 459.95178 | K15: =J15+K14 -> 12455.494
A16: Caleta Olivia | B16: Comodoro Rivadavia | C16: 84 | D16: =C16*$E$4 -> 1512 | E16: =D16+E15 -> 13698 | F16: =C16*$G$4 -> 1361.1335 | G16: =F16+G15 -> 12331.221 | H16: =C16*$I$4 -> 1455.5246 | I16: =H16+I15 -> 13186.36 | J16: =C16*$K$4 -> 1545.438 | K16: =J16+K15 -> 14000.932
A17: Comodoro Rivadavia | B17: Astra | C17: 19 | D17: =C17*$E$4 -> 342 | E17: =D17+E16 -> 14040 | F17: =C17*$G$4 -> 307.87543 | G17: =F17+G16 -> 12639.097 | H17: =C17*$I$4 -> 329.22581 | I17: =H17+I16 -> 13515.586 | J17: =C17*$K$4 -> 349.56335 | K17: =J17+K16 -> 14350.495
A18: Astra | B18: Pampa Salamanca | C18: 60 | D18: =C18*$E$4 -> 1080 | E18: =D18+E17 -> 15120 | F18: =C18*$G$4 -> 972.2382 | G18: =F18+G17 -> 13611.335 | H18: =C18*$I$4 -> 1039.6604 | I18: =H18+I17 -> 14555.246 | J18: =C18*$K$4 -> 1103.8843 | K18: =J18+K17 -> 15454.38
... A34: Teniente Origone | B34: Bahia Blanca | C34: 74 | D34: =C34*$E$4 -> 1332 | E34: =D34+E33 -> 36054 | F34: =C34*$G$4 -> 1199.0938 | G34: =F34+G33 -> 32456.552 | H34: =C34*$I$4 -> 1282.2479 | I34: =H34+I33 -> 34707.331 | J34: =C34*$K$4 -> 1361.4573 | K34: =J34+K33 -> 36851.336
A35: Compensación necesaria (ps/(nm.km)) | C35: =IF(E35 < 0, E35/'DATOS DE EQUIPOS'!U10, 0) -> 0 | E35: ='DATOS DE EQUIPOS'!B13-E34 -> 63946 | G35: ='DATOS DE EQUIPOS'!$B$13-G34 -> 67543.448 | I35: ='DATOS DE EQUIPOS'!$B$13-I34 -> 65292.669 | K35: ='DATOS DE EQUIPOS'!$B$13-K34 -> 63148.664
C36: No necesitamos para ningun landa | E36: Diferencia positiva | G36: Diferencia positiva | I36: Diferencia positiva | K36: Diferencia positiva
I40: Fórmula para calcular el coeficiente de dispersión para otro landa
E41: Canal (ITU-T) | F41: Frecuencia (THz) | G41: Longitud de Onda (nm)
E42: C14 | F42: 191.4 | G42: 1566.31
E43: C15 | F43: 191.5 | G43: 1565.5
E44: C16 | F44: 191.6 | G44: 1564.68
E45: C17 | F45: 191.7 | G45: 1563.86
E46: C18 | F46: 191.8 | G46: 1563.05
E47: C19 | F47: 191.9 | G47: 1562.23
E48: C20 | F48: 192 | G48: 1561.42
E49: C21 | F49: 192.1 | G49: 1560.61
E50: C22 | F50: 192.2 | G50: 1559.79
E51: C23 | F51: 192.3 | G51: 1558.98
E52: C24 | F52: 192.4 | G52: 1558.17
E53: C25 | F53: 192.5 | G53: 1557.36
... E89: C61 | F89: 196.1 | G89: 1528.77

Sheet PMD
A1: CALCULO PMD
A2: INICIO | B2: DESTINO | C2: DISTANCIA (Km) | D2: RETARDO DIF DE GRUPO (ps)
A3: Rio Gallegos | B3: Coy Aike | C3: 87 | D3: =SQRT(C3)*'DATOS DE EQUIPOS'!$N$15 -> 0.93273791
A4: Coy Aike | B4: Cañadon de las Vacas | C4: 75 | D4: =SQRT(C4)*'DATOS DE EQUIPOS'!$N$15 -> 0.8660254
A5: Cañadon de las Vacas | B5: Luis Piedrabuena | C5: 78 | D5: =SQRT(C5)*'DATOS DE EQUIPOS'!$N$15 -> 0.88317609
A6: Luis Piedrabuena | B6: Lago Posadas | C6: 34 | D6: =SQRT(C6)*'DATOS DE EQUIPOS'!$N$15 -> 0.58309519
A7: Lago Posadas | B7: Puerto San Julian | C7: 90 | D7: =SQRT(C7)*'DATOS DE EQUIPOS'!$N$15 -> 0.9486833
A8: Puerto San Julian | B8: El Salado | C8: 74 | D8: =SQRT(C8)*'DATOS DE EQUIPOS'!$N$15 -> 0.86023253
A9: El Salado | B9: Tres Cerros | C9: 67 | D9: =SQRT(C9)*'DATOS DE EQUIPOS'!$N$15 -> 0.81853528
A10: Tres Cerros | B10: Estancia La Calandria | C10: 66 | D10: =SQRT(C10)*'DATOS DE EQUIPOS'!$N$15 -> 0.81240384
A11: Estancia La Calandria | B11: Jaramillo | C11: 81 | D11: =SQRT(C11)*'DATOS DE EQUIPOS'!$N$15 -> 0.9
A12: Jaramillo | B12: Caleta Olivia | C12: 25 | D12: =SQRT(C12)*'DATOS DE EQUIPOS'!$N$15 -> 0.5
A13: Caleta Olivia | B13: Comodoro Rivadavia | C13: 84 | D13: =SQRT(C13)*'DATOS DE EQUIPOS'!$N$15 -> 0.91651514
A14: Comodoro Rivadavia | B14: Astra | C14: 19 | D14: =SQRT(C14)*'DATOS DE EQUIPOS'!$N$15 -> 0.43588989
... A31: Teniente Origone | B31: Bahia Blanca | C31: 74 | D31: =SQRT(C31)*'DATOS DE EQUIPOS'!$N$15 -> 0.86023253
A32: RETARDO DIF DE GRUPO TOTAL (ps) | D32: =SQRT(SUMSQ(D3:D31)) -> 4.4754888

Sheet TABLA CANALES
B1: RIO GALLEGOS | I1: CALETA OLIVIA | P1: BAHÍA BLANCA | X1: NEUQUÉN | AF1: SAN RAFAEL
B2: Canal (ITU-T) | C2: Frecuencia (THz) | D2: Longitud de Onda (nm) | E2: A El Condor | F2: A Gob. Mayer | G2: A Coy Aike | I2: Canal (ITU-T) | J2: Frecuencia (THz) | K2: Longitud de Onda (nm) | L2: A Jaramillo | M2: A Pico Truncado | N2: A Comodoro Rivadavia | P2: Canal (ITU-T) | Q2: Frecuencia (THz) | R2: Longitud de Onda (nm) | S2: A Teniente Origone | T2: A Juan Cousté | U2: A Tres Arroyos | X2: Canal (ITU-T) | Y2: Frecuencia (THz) | Z2: Longitud de Onda (nm) | AA2: A Arroyito | AB2: A General Roca | AC2: A Sargento Vidal | AF2: Canal (ITU-T) | AG2: Frecuencia (THz) | AH2: Longitud de Onda (nm) | AI2: A General Alvear | AJ2: A Rincón del Atuel | AK2: A Santa Isabel
B3: C14 | C3: 191.4 | D3: 1566.31 | I3: C14 | J3: 191.4 | K3: 1566.31 | P3: C14 | Q3: 191.4 | R3: 1566.31 | X3: C14 | Y3: 191.4 | Z3: 1566.31 | AF3: C14 | AG3: 191.4 | AH3: 1566.31
B4: C15 | C4: 191.5 | D4: 1565.5 | I4: C15 | J4: 191.5 | K4: 1565.5 | P4: C15 | Q4: 191.5 | R4: 1565.5 | X4: C15 | Y4: 191.5 | Z4: 1565.5 | AF4: C15 | AG4: 191.5 | AH4: 1565.5
B5: C16 | C5: 191.6 | D5: 1564.68 | I5: C16 | J5: 191.6 | K5: 1564.68 | P5: C16 | Q5: 191.6 | R5: 1564.68 | X5: C16 | Y5: 191.6 | Z5: 1564.68 | AF5: C16 | AG5: 191.6 | AH5: 1564.68
B6: C17 | C6: 191.7 | D6: 1563.86 | I6: C17 | J6: 191.7 | K6: 1563.86 | P6: C17 | Q6: 191.7 | R6: 1563.86 | X6: C17 | Y6: 191.7 | Z6: 1563.86 | AF6: C17 | AG6: 191.7 | AH6: 1563.86
B7: C18 | C7: 191.8 | D7: 1563.05 | I7: C18 | J7: 191.8 | K7: 1563.05 | P7: C18 | Q7: 191.8 | R7: 1563.05 | X7: C18 | Y7: 191.8 | Z7: 1563.05 | AF7: C18 | AG7: 191.8 | AH7: 1563.05
B8: C19 | C8: 191.9 | D8: 1562.23 | I8: C19 | J8: 191.9 | K8: 1562.23 | P8: C19 | Q8: 191.9 | R8: 1562.23 | X8: C19 | Y8: 191.9 | Z8: 1562.23 | AF8: C19 | AG8: 191.9 | AH8: 1562.23
B9: C20 | C9: 192 | D9: 1561.42 | I9: C20 | J9: 192 | K9: 1561.42 | P9: C20 | Q9: 192 | R9: 1561.42 | X9: C20 | Y9: 192 | Z9: 1561.42 | AF9: C20 | AG9: 192 | AH9: 1561.42
B10: C21 | C10: 192.1 | D10: 1560.61 | I10: C21 | J10: 192.1 | K10: 1560.61 | P10: C21 | Q10: 192.1 | R10: 1560.61 | X10: C21 | Y10: 192.1 | Z10: 1560.61 | AF10: C21 | AG10: 192.1 | AH10: 1560.61
B11: C22 | C11: 192.2 | D11: 1559.79 | I11: C22 | J11: 192.2 | K11: 1559.79 | P11: C22 | Q11: 192.2 | R11: 1559.79 | S11: 1 G | X11: C22 | Y11: 192.2 | Z11: 1559.79 | AF11: C22 | AG11: 192.2 | AH11: 1559.79
B12: C23 | C12: 192.3 | D12: 1558.98 | I12: C23 | J12: 192.3 | K12: 1558.98 | P12: C23 | Q12: 192.3 | R12: 1558.98 | S12: 1 G | X12: C23 | Y12: 192.3 | Z12: 1558.98 | AF12: C23 | AG12: 192.3 | AH12: 1558.98
B13: C24 | C13: 192.4 | D13: 1558.17 | I13: C24 | J13: 192.4 | K13: 1558.17 | P13: C24 | Q13: 192.4 | R13: 1558.17 | S13: 1 G | X13: C24 | Y13: 192.4 | Z13: 1558.17 | AF13: C24 | AG13: 192.4 | AH13: 1558.17
B14: C25 | C14: 192.5 | D14: 1557.36 | I14: C25 | J14: 192.5 | K14: 1557.36 | P14: C25 | Q14: 192.5 | R14: 1557.36 | S14: 1 G | X14: C25 | Y14: 192.5 | Z14: 1557.36 | AF14: C25 | AG14: 192.5 | AH14: 1557.36
B15: C26 | C15: 192.6 | D15: 1556.55 | I15: C26 | J15: 192.6 | K15: 1556.55 | P15: C26 | Q15: 192.6 | R15: 1556.55 | S15: 1 G | X15: C26 | Y15: 192.6 | Z15: 1556.55 | AF15: C26 | AG15: 192.6 | AH15: 1556.55
B16: C27 | C16: 192.7 | D16: 1555.75 | I16: C27 | J16: 192.7 | K16: 1555.75 | P16: C27 | Q16: 192.7 | R16: 1555.75 | S16: 1 G | X16: C27 | Y16: 192.7 | Z16: 1555.75 | AF16: C27 | AG16: 192.7 | AH16: 1555.75
B17: C28 | C17: 192.8 | D17: 1554.94 | I17: C28 | J17: 192.8 | K17: 1554.94 | P17: C28 | Q17: 192.8 | R17: 1554.94 | S17: 1 G | X17: C28 | Y17: 192.8 | Z17: 1554.94 | AF17: C28 | AG17: 192.8 | AH17: 1554.94
B18: C29 | C18: 192.9 | D18: 1554.13 | I18: C29 | J18: 192.9 | K18: 1554.13 | P18: C29 | Q18: 192.9 | R18: 1554.13 | S18: 1 G | X18: C29 | Y18: 192.9 | Z18: 1554.13 | AA18: 1 G | AF18: C29 | AG18: 192.9 | AH18: 1554.13
B19: C30 | C19: 193 | D19: 1553.33 | I19: C30 | J19: 193 | K19: 1553.33 | P19: C30 | Q19: 193 | R19: 1553.33 | S19: 1 G | X19: C30 | Y19: 193 | Z19: 1553.33 | AA19: 1 G | AF19: C30 | AG19: 193 | AH19: 1553.33
B20: C31 | C20: 193.1 | D20: 1552.52 | I20: C31 | J20: 193.1 | K20: 1552.52 | P20: C31 | Q20: 193.1 | R20: 1552.52 | S20: 1 G | X20: C31 | Y20: 193.1 | Z20: 1552.52 | AA20: 1 G | AF20: C31 | AG20: 193.1 | AH20: 1552.52
B21: C32 | C21: 193.2 | D21: 1551.72 | I21: C32 | J21: 193.2 | K21: 1551.72 | P21: C32 | Q21: 193.2 | R21: 1551.72 | S21: 1 G | X21: C32 | Y21: 193.2 | Z21: 1551.72 | AA21: 1 G | AF21: C32 | AG21: 193.2 | AH21: 1551.72
B22: C33 | C22: 193.3 | D22: 1550.92 | I22: C33 | J22: 193.3 | K22: 1550.92 | N22: 1 G | P22: C33 | Q22: 193.3 | R22: 1550.92 | S22: 1 G | X22: C33 | Y22: 193.3 | Z22: 1550.92 | AA22: 1 G | AF22: C33 | AG22: 193.3 | AH22: 1550.92
B23: C34 | C23: 193.4 | D23: 1550.12 | F23: 1 G | G23: 1 G | I23: C34 | J23: 193.4 | K23: 1550.12 | L23: 1 G | M23: 1 G | N23: 1 G | P23: C34 | Q23: 193.4 | R23: 1550.12 | S23: 1 G | X23: C34 | Y23: 193.4 | Z23: 1550.12 | AA23: 1 G | AB23: 1 G | AC23: 1 G | AF23: C34 | AG23: 193.4 | AH23: 1550.12 | AJ23: 1 G
B24: C35 | C24: 193.5 | D24: 1549.32 | F24: 1 G | G24: 1 G | I24: C35 | J24: 193.5 | K24: 1549.32 | L24: 1 G | M24: 1 G | N24: 1 G | P24: C35 | Q24: 193.5 | R24: 1549.32 | X24: C35 | Y24: 193.5 | Z24: 1549.32 | AA24: 1 G | AB24: 1 G | AC24: 1 G | AF24: C35 | AG24: 193.5 | AH24: 1549.32 | AJ24: 1 G
B25: C36 | C25: 193.6 | D25: 1548.51 | F25: 1 G | G25: 1 G | I25: C36 | J25: 193.6 | K25: 1548.51 | L25: 1 G | M25: 1 G | N25: 1 G | P25: C36 | Q25: 193.6 | R25: 1548.51 | X25: C36 | Y25: 193.6 | Z25: 1548.51 | AA25: 1 G | AB25: 1 G | AC25: 1 G | AF25: C36 | AG25: 193.6 | AH25: 1548.51 | AJ25: 1 G
B26: C37 | C26: 193.7 | D26: 1547.72 | F26: 1 G | G26: 1 G | I26: C37 | J26: 193.7 | K26: 1547.72 | L26: 1 G | M26: 1 G | P26: C37 | Q26: 193.7 | R26: 1547.72 | S26: 100 G | X26: C37 | Y26: 193.7 | Z26: 1547.72 | AB26: 1 G | AC26: 1 G | AF26: C37 | AG26: 193.7 | AH26: 1547.72 | AJ26: 1 G
B27: C38 | C27: 193.8 | D27: 1546.92 | I27: C38 | J27: 193.8 | K27: 1546.92 | P27: C38 | Q27: 193.8 | R27: 1546.92 | S27: 100 G | X27: C38 | Y27: 193.8 | Z27: 1546.92 | AF27: C38 | AG27: 193.8 | AH27: 1546.92
B28: C39 | C28: 193.9 | D28: 1546.12 | E28: 100 G | I28: C39 | J28: 193.9 | K28: 1546.12 | N28: 100 G | P28: C39 | Q28: 193.9 | R28: 1546.12 | S28: 100 G | X28: C39 | Y28: 193.9 | Z28: 1546.12 | AA28: 100 G | AF28: C39 | AG28: 193.9 | AH28: 1546.12
B29: C40 | C29: 194 | D29: 1545.32 | E29: 100 G | F29: 100G | G29: 100G | I29: C40 | J29: 194 | K29: 1545.32 | L29: 100 G | M29: 100 G | N29: 100 G | P29: C40 | Q29: 194 | R29: 1545.32 | S29: 100 G | X29: C40 | Y29: 194 | Z29: 1545.32 | AA29: 100 G | AB29: 100 G | AC29: 100 G | AF29: C40 | AG29: 194 | AH29: 1545.32 | AI29: 100 G | AJ29: 100 G
B30: C41 | C30: 194.1 | D30: 1544.53 | I30: C41 | J30: 194.1 | K30: 1544.53 | P30: C41 | Q30: 194.1 | R30: 1544.53 | S30: 100 G | X30: C41 | Y30: 194.1 | Z30: 1544.53 | AA30: 100 G | AF30: C41 | AG30: 194.1 | AH30: 1544.53
B31: C42 | C31: 194.2 | D31: 1543.73 | I31: C42 | J31: 194.2 | K31: 1543.73 | P31: C42 | Q31: 194.2 | R31: 1543.73 | X31: C42 | Y31: 194.2 | Z31: 1543.73 | AF31: C42 | AG31: 194.2 | AH31: 1543.73
B32: C43 | C32: 194.3 | D32: 1542.94 | E32: 10 G | F32: 10 G | G32: 10 G | I32: C43 | J32: 194.3 | K32: 1542.94 | L32: 10 G | M32: 10 G | N32: 10 G | P32: C43 | Q32: 194.3 | R32: 1542.94 | X32: C43 | Y32: 194.3 | Z32: 1542.94 | AB32: 10 G | AC32: 10 G | AF32: C43 | AG32: 194.3 | AH32: 1542.94 | AI32: 10 G | AJ32: 10 G
B33: C44 | C33: 194.4 | D33: 1542.14 | E33: 10 G | I33: C44 | J33: 194.4 | K33: 1542.14 | N33: 10 G | P33: C44 | Q33: 194.4 | R33: 1542.14 | S33: 10 G | X33: C44 | Y33: 194.4 | Z33: 1542.14 | AA33: 10 G | AF33: C44 | AG33: 194.4 | AH33: 1542.14
B34: C45 | C34: 194.5 | D34: 1541.35 | I34: C45 | J34: 194.5 | K34: 1541.35 | P34: C45 | Q34: 194.5 | R34: 1541.35 | S34: 10 G | X34: C45 | Y34: 194.5 | Z34: 1541.35 | AA34: 10 G | AF34: C45 | AG34: 194.5 | AH34: 1541.35
B35: C46 | C35: 194.6 | D35: 1540.56 | I35: C46 | J35: 194.6 | K35: 1540.56 | P35: C46 | Q35: 194.6 | R35: 1540.56 | S35: 10 G | X35: C46 | Y35: 194.6 | Z35: 1540.56 | AA35: 10 G | AF35: C46 | AG35: 194.6 | AH35: 1540.56
B36: C47 | C36: 194.7 | D36: 1539.77 | I36: C47 | J36: 194.7 | K36: 1539.77 | P36: C47 | Q36: 194.7 | R36: 1539.77 | S36: 10 G | X36: C47 | Y36: 194.7 | Z36: 1539.77 | AF36: C47 | AG36: 194.7 | AH36: 1539.77
B37: C48 | C37: 194.8 | D37: 1538.98 | I37: C48 | J37: 194.8 | K37: 1538.98 | P37: C48 | Q37: 194.8 | R37: 1538.98 | S37: 10 G | X37: C48 | Y37: 194.8 | Z37: 1538.98 | AF37: C48 | AG37: 194.8 | AH37: 1538.98
B38: C49 | C38: 194.9 | D38: 1538.19 | I38: C49 | J38: 194.9 | K38: 1538.19 | P38: C49 | Q38: 194.9 | R38: 1538.19 | X38: C49 | Y38: 194.9 | Z38: 1538.19 | AF38: C49 | AG38: 194.9 | AH38: 1538.19
B39: C50 | C39: 195 | D39: 1537.4 | I39: C50 | J39: 195 | K39: 1537.4 | P39: C50 | Q39: 195 | R39: 1537.4 | X39: C50 | Y39: 195 | Z39: 1537.4 | AF39: C50 | AG39: 195 | AH39: 1537.4
B40: C51 | C40: 195.1 | D40: 1536.61 | I40: C51 | J40: 195.1 | K40: 1536.61 | P40: C51 | Q40: 195.1 | R40: 1536.61 | X40: C51 | Y40: 195.1 | Z40: 1536.61 | AF40: C51 | AG40: 195.1 | AH40: 1536.61
...
